2020-04-27 21:13:28,415 - __mp_main__ - ERROR - Uncaught exception
Traceback (most recent call last):
  File "<string>", line 1, in <module>
  File "/Library/Frameworks/Python.framework/Versions/3.8/lib/python3.8/multiprocessing/spawn.py", line 116, in spawn_main
    exitcode = _main(fd, parent_sentinel)
  File "/Library/Frameworks/Python.framework/Versions/3.8/lib/python3.8/multiprocessing/spawn.py", line 125, in _main
    prepare(preparation_data)
  File "/Library/Frameworks/Python.framework/Versions/3.8/lib/python3.8/multiprocessing/spawn.py", line 236, in prepare
    _fixup_main_from_path(data['init_main_from_path'])
  File "/Library/Frameworks/Python.framework/Versions/3.8/lib/python3.8/multiprocessing/spawn.py", line 287, in _fixup_main_from_path
    main_content = runpy.run_path(main_path,
  File "/Library/Frameworks/Python.framework/Versions/3.8/lib/python3.8/runpy.py", line 263, in run_path
    return _run_module_code(code, init_globals, run_name,
  File "/Library/Frameworks/Python.framework/Versions/3.8/lib/python3.8/runpy.py", line 96, in _run_module_code
    _run_code(code, mod_globals, init_globals,
  File "/Library/Frameworks/Python.framework/Versions/3.8/lib/python3.8/runpy.py", line 86, in _run_code
    exec(code, run_globals)
  File "/Users/rohit/Documents/randomExperiments/pipeline.py", line 49, in <module>
    import r0AverageTest as r0AverageTest
  File "/Users/rohit/Documents/randomExperiments/r0AverageTest.py", line 17, in <module>
    import regressions as rgx
  File "/Users/rohit/Documents/randomExperiments/regressions.py", line 109
    return round(coeffs[0]*b + coeffs[1], 2)
    ^
IndentationError: expected an indented block
2020-04-27 21:13:29,525 - __mp_main__ - ERROR - Uncaught exception
Traceback (most recent call last):
  File "<string>", line 1, in <module>
  File "/Library/Frameworks/Python.framework/Versions/3.8/lib/python3.8/multiprocessing/spawn.py", line 116, in spawn_main
    exitcode = _main(fd, parent_sentinel)
  File "/Library/Frameworks/Python.framework/Versions/3.8/lib/python3.8/multiprocessing/spawn.py", line 125, in _main
    prepare(preparation_data)
  File "/Library/Frameworks/Python.framework/Versions/3.8/lib/python3.8/multiprocessing/spawn.py", line 236, in prepare
    _fixup_main_from_path(data['init_main_from_path'])
  File "/Library/Frameworks/Python.framework/Versions/3.8/lib/python3.8/multiprocessing/spawn.py", line 287, in _fixup_main_from_path
    main_content = runpy.run_path(main_path,
  File "/Library/Frameworks/Python.framework/Versions/3.8/lib/python3.8/runpy.py", line 263, in run_path
    return _run_module_code(code, init_globals, run_name,
  File "/Library/Frameworks/Python.framework/Versions/3.8/lib/python3.8/runpy.py", line 96, in _run_module_code
    _run_code(code, mod_globals, init_globals,
  File "/Library/Frameworks/Python.framework/Versions/3.8/lib/python3.8/runpy.py", line 86, in _run_code
    exec(code, run_globals)
  File "/Users/rohit/Documents/randomExperiments/pipeline.py", line 49, in <module>
    import r0AverageTest as r0AverageTest
  File "/Users/rohit/Documents/randomExperiments/r0AverageTest.py", line 17, in <module>
    import regressions as rgx
  File "/Users/rohit/Documents/randomExperiments/regressions.py", line 109
    return round(coeffs[0]*b + coeffs[1], 2)
    ^
IndentationError: expected an indented block
2020-04-27 21:13:30,563 - __mp_main__ - ERROR - Uncaught exception
Traceback (most recent call last):
  File "<string>", line 1, in <module>
  File "/Library/Frameworks/Python.framework/Versions/3.8/lib/python3.8/multiprocessing/spawn.py", line 116, in spawn_main
    exitcode = _main(fd, parent_sentinel)
  File "/Library/Frameworks/Python.framework/Versions/3.8/lib/python3.8/multiprocessing/spawn.py", line 125, in _main
    prepare(preparation_data)
  File "/Library/Frameworks/Python.framework/Versions/3.8/lib/python3.8/multiprocessing/spawn.py", line 236, in prepare
    _fixup_main_from_path(data['init_main_from_path'])
  File "/Library/Frameworks/Python.framework/Versions/3.8/lib/python3.8/multiprocessing/spawn.py", line 287, in _fixup_main_from_path
    main_content = runpy.run_path(main_path,
  File "/Library/Frameworks/Python.framework/Versions/3.8/lib/python3.8/runpy.py", line 263, in run_path
    return _run_module_code(code, init_globals, run_name,
  File "/Library/Frameworks/Python.framework/Versions/3.8/lib/python3.8/runpy.py", line 96, in _run_module_code
    _run_code(code, mod_globals, init_globals,
  File "/Library/Frameworks/Python.framework/Versions/3.8/lib/python3.8/runpy.py", line 86, in _run_code
    exec(code, run_globals)
  File "/Users/rohit/Documents/randomExperiments/pipeline.py", line 49, in <module>
    import r0AverageTest as r0AverageTest
  File "/Users/rohit/Documents/randomExperiments/r0AverageTest.py", line 17, in <module>
    import regressions as rgx
  File "/Users/rohit/Documents/randomExperiments/regressions.py", line 109
    return round(coeffs[0]*b + coeffs[1], 2)
    ^
IndentationError: expected an indented block
2020-04-27 21:13:34,461 - __mp_main__ - ERROR - Uncaught exception
Traceback (most recent call last):
  File "<string>", line 1, in <module>
  File "/Library/Frameworks/Python.framework/Versions/3.8/lib/python3.8/multiprocessing/spawn.py", line 116, in spawn_main
    exitcode = _main(fd, parent_sentinel)
  File "/Library/Frameworks/Python.framework/Versions/3.8/lib/python3.8/multiprocessing/spawn.py", line 125, in _main
    prepare(preparation_data)
  File "/Library/Frameworks/Python.framework/Versions/3.8/lib/python3.8/multiprocessing/spawn.py", line 236, in prepare
    _fixup_main_from_path(data['init_main_from_path'])
  File "/Library/Frameworks/Python.framework/Versions/3.8/lib/python3.8/multiprocessing/spawn.py", line 287, in _fixup_main_from_path
    main_content = runpy.run_path(main_path,
  File "/Library/Frameworks/Python.framework/Versions/3.8/lib/python3.8/runpy.py", line 263, in run_path
    return _run_module_code(code, init_globals, run_name,
  File "/Library/Frameworks/Python.framework/Versions/3.8/lib/python3.8/runpy.py", line 96, in _run_module_code
    _run_code(code, mod_globals, init_globals,
  File "/Library/Frameworks/Python.framework/Versions/3.8/lib/python3.8/runpy.py", line 86, in _run_code
    exec(code, run_globals)
  File "/Users/rohit/Documents/randomExperiments/pipeline.py", line 49, in <module>
    import r0AverageTest as r0AverageTest
  File "/Users/rohit/Documents/randomExperiments/r0AverageTest.py", line 17, in <module>
    import regressions as rgx
  File "/Users/rohit/Documents/randomExperiments/regressions.py", line 109
    return round(coeffs[0]*b + coeffs[1], 2)
    ^
IndentationError: expected an indented block
2020-04-27 21:13:34,548 - __mp_main__ - ERROR - Uncaught exception
Traceback (most recent call last):
  File "<string>", line 1, in <module>
  File "/Library/Frameworks/Python.framework/Versions/3.8/lib/python3.8/multiprocessing/spawn.py", line 116, in spawn_main
    exitcode = _main(fd, parent_sentinel)
  File "/Library/Frameworks/Python.framework/Versions/3.8/lib/python3.8/multiprocessing/spawn.py", line 125, in _main
    prepare(preparation_data)
  File "/Library/Frameworks/Python.framework/Versions/3.8/lib/python3.8/multiprocessing/spawn.py", line 236, in prepare
    _fixup_main_from_path(data['init_main_from_path'])
  File "/Library/Frameworks/Python.framework/Versions/3.8/lib/python3.8/multiprocessing/spawn.py", line 287, in _fixup_main_from_path
    main_content = runpy.run_path(main_path,
  File "/Library/Frameworks/Python.framework/Versions/3.8/lib/python3.8/runpy.py", line 263, in run_path
    return _run_module_code(code, init_globals, run_name,
  File "/Library/Frameworks/Python.framework/Versions/3.8/lib/python3.8/runpy.py", line 96, in _run_module_code
    _run_code(code, mod_globals, init_globals,
  File "/Library/Frameworks/Python.framework/Versions/3.8/lib/python3.8/runpy.py", line 86, in _run_code
    exec(code, run_globals)
  File "/Users/rohit/Documents/randomExperiments/pipeline.py", line 49, in <module>
    import r0AverageTest as r0AverageTest
  File "/Users/rohit/Documents/randomExperiments/r0AverageTest.py", line 17, in <module>
    import regressions as rgx
  File "/Users/rohit/Documents/randomExperiments/regressions.py", line 109
    return round(coeffs[0]*b + coeffs[1], 2)
    ^
IndentationError: expected an indented block
2020-04-27 21:13:34,548 - __mp_main__ - ERROR - Uncaught exception
Traceback (most recent call last):
  File "<string>", line 1, in <module>
  File "/Library/Frameworks/Python.framework/Versions/3.8/lib/python3.8/multiprocessing/spawn.py", line 116, in spawn_main
    exitcode = _main(fd, parent_sentinel)
  File "/Library/Frameworks/Python.framework/Versions/3.8/lib/python3.8/multiprocessing/spawn.py", line 125, in _main
    prepare(preparation_data)
  File "/Library/Frameworks/Python.framework/Versions/3.8/lib/python3.8/multiprocessing/spawn.py", line 236, in prepare
    _fixup_main_from_path(data['init_main_from_path'])
  File "/Library/Frameworks/Python.framework/Versions/3.8/lib/python3.8/multiprocessing/spawn.py", line 287, in _fixup_main_from_path
    main_content = runpy.run_path(main_path,
  File "/Library/Frameworks/Python.framework/Versions/3.8/lib/python3.8/runpy.py", line 263, in run_path
    return _run_module_code(code, init_globals, run_name,
  File "/Library/Frameworks/Python.framework/Versions/3.8/lib/python3.8/runpy.py", line 96, in _run_module_code
    _run_code(code, mod_globals, init_globals,
  File "/Library/Frameworks/Python.framework/Versions/3.8/lib/python3.8/runpy.py", line 86, in _run_code
    exec(code, run_globals)
  File "/Users/rohit/Documents/randomExperiments/pipeline.py", line 49, in <module>
    import r0AverageTest as r0AverageTest
  File "/Users/rohit/Documents/randomExperiments/r0AverageTest.py", line 17, in <module>
    import regressions as rgx
  File "/Users/rohit/Documents/randomExperiments/regressions.py", line 109
    return round(coeffs[0]*b + coeffs[1], 2)
    ^
IndentationError: expected an indented block
2020-04-27 21:13:37,997 - __mp_main__ - ERROR - Uncaught exception
Traceback (most recent call last):
  File "<string>", line 1, in <module>
  File "/Library/Frameworks/Python.framework/Versions/3.8/lib/python3.8/multiprocessing/spawn.py", line 116, in spawn_main
    exitcode = _main(fd, parent_sentinel)
  File "/Library/Frameworks/Python.framework/Versions/3.8/lib/python3.8/multiprocessing/spawn.py", line 125, in _main
    prepare(preparation_data)
  File "/Library/Frameworks/Python.framework/Versions/3.8/lib/python3.8/multiprocessing/spawn.py", line 236, in prepare
    _fixup_main_from_path(data['init_main_from_path'])
  File "/Library/Frameworks/Python.framework/Versions/3.8/lib/python3.8/multiprocessing/spawn.py", line 287, in _fixup_main_from_path
    main_content = runpy.run_path(main_path,
  File "/Library/Frameworks/Python.framework/Versions/3.8/lib/python3.8/runpy.py", line 263, in run_path
    return _run_module_code(code, init_globals, run_name,
  File "/Library/Frameworks/Python.framework/Versions/3.8/lib/python3.8/runpy.py", line 96, in _run_module_code
    _run_code(code, mod_globals, init_globals,
  File "/Library/Frameworks/Python.framework/Versions/3.8/lib/python3.8/runpy.py", line 86, in _run_code
    exec(code, run_globals)
  File "/Users/rohit/Documents/randomExperiments/pipeline.py", line 49, in <module>
    import r0AverageTest as r0AverageTest
  File "/Users/rohit/Documents/randomExperiments/r0AverageTest.py", line 17, in <module>
    import regressions as rgx
  File "/Users/rohit/Documents/randomExperiments/regressions.py", line 109
    return round(coeffs[0]*b + coeffs[1], 2)
    ^
IndentationError: expected an indented block
2020-04-27 21:13:38,792 - __mp_main__ - ERROR - Uncaught exception
Traceback (most recent call last):
  File "<string>", line 1, in <module>
  File "/Library/Frameworks/Python.framework/Versions/3.8/lib/python3.8/multiprocessing/spawn.py", line 116, in spawn_main
    exitcode = _main(fd, parent_sentinel)
  File "/Library/Frameworks/Python.framework/Versions/3.8/lib/python3.8/multiprocessing/spawn.py", line 125, in _main
    prepare(preparation_data)
  File "/Library/Frameworks/Python.framework/Versions/3.8/lib/python3.8/multiprocessing/spawn.py", line 236, in prepare
    _fixup_main_from_path(data['init_main_from_path'])
  File "/Library/Frameworks/Python.framework/Versions/3.8/lib/python3.8/multiprocessing/spawn.py", line 287, in _fixup_main_from_path
    main_content = runpy.run_path(main_path,
  File "/Library/Frameworks/Python.framework/Versions/3.8/lib/python3.8/runpy.py", line 263, in run_path
    return _run_module_code(code, init_globals, run_name,
  File "/Library/Frameworks/Python.framework/Versions/3.8/lib/python3.8/runpy.py", line 96, in _run_module_code
    _run_code(code, mod_globals, init_globals,
  File "/Library/Frameworks/Python.framework/Versions/3.8/lib/python3.8/runpy.py", line 86, in _run_code
    exec(code, run_globals)
  File "/Users/rohit/Documents/randomExperiments/pipeline.py", line 49, in <module>
    import r0AverageTest as r0AverageTest
  File "/Users/rohit/Documents/randomExperiments/r0AverageTest.py", line 17, in <module>
    import regressions as rgx
  File "/Users/rohit/Documents/randomExperiments/regressions.py", line 109
    return round(coeffs[0]*b + coeffs[1], 2)
    ^
IndentationError: expected an indented block
2020-04-27 21:13:39,609 - __mp_main__ - ERROR - Uncaught exception
Traceback (most recent call last):
  File "<string>", line 1, in <module>
  File "/Library/Frameworks/Python.framework/Versions/3.8/lib/python3.8/multiprocessing/spawn.py", line 116, in spawn_main
    exitcode = _main(fd, parent_sentinel)
  File "/Library/Frameworks/Python.framework/Versions/3.8/lib/python3.8/multiprocessing/spawn.py", line 125, in _main
    prepare(preparation_data)
  File "/Library/Frameworks/Python.framework/Versions/3.8/lib/python3.8/multiprocessing/spawn.py", line 236, in prepare
    _fixup_main_from_path(data['init_main_from_path'])
  File "/Library/Frameworks/Python.framework/Versions/3.8/lib/python3.8/multiprocessing/spawn.py", line 287, in _fixup_main_from_path
    main_content = runpy.run_path(main_path,
  File "/Library/Frameworks/Python.framework/Versions/3.8/lib/python3.8/runpy.py", line 263, in run_path
    return _run_module_code(code, init_globals, run_name,
  File "/Library/Frameworks/Python.framework/Versions/3.8/lib/python3.8/runpy.py", line 96, in _run_module_code
    _run_code(code, mod_globals, init_globals,
  File "/Library/Frameworks/Python.framework/Versions/3.8/lib/python3.8/runpy.py", line 86, in _run_code
    exec(code, run_globals)
  File "/Users/rohit/Documents/randomExperiments/pipeline.py", line 49, in <module>
    import r0AverageTest as r0AverageTest
  File "/Users/rohit/Documents/randomExperiments/r0AverageTest.py", line 17, in <module>
    import regressions as rgx
  File "/Users/rohit/Documents/randomExperiments/regressions.py", line 109
    return round(coeffs[0]*b + coeffs[1], 2)
    ^
IndentationError: expected an indented block
2020-04-27 21:13:43,173 - __mp_main__ - ERROR - Uncaught exception
Traceback (most recent call last):
  File "<string>", line 1, in <module>
  File "/Library/Frameworks/Python.framework/Versions/3.8/lib/python3.8/multiprocessing/spawn.py", line 116, in spawn_main
    exitcode = _main(fd, parent_sentinel)
  File "/Library/Frameworks/Python.framework/Versions/3.8/lib/python3.8/multiprocessing/spawn.py", line 125, in _main
    prepare(preparation_data)
  File "/Library/Frameworks/Python.framework/Versions/3.8/lib/python3.8/multiprocessing/spawn.py", line 236, in prepare
    _fixup_main_from_path(data['init_main_from_path'])
  File "/Library/Frameworks/Python.framework/Versions/3.8/lib/python3.8/multiprocessing/spawn.py", line 287, in _fixup_main_from_path
    main_content = runpy.run_path(main_path,
  File "/Library/Frameworks/Python.framework/Versions/3.8/lib/python3.8/runpy.py", line 263, in run_path
    return _run_module_code(code, init_globals, run_name,
  File "/Library/Frameworks/Python.framework/Versions/3.8/lib/python3.8/runpy.py", line 96, in _run_module_code
    _run_code(code, mod_globals, init_globals,
  File "/Library/Frameworks/Python.framework/Versions/3.8/lib/python3.8/runpy.py", line 86, in _run_code
    exec(code, run_globals)
  File "/Users/rohit/Documents/randomExperiments/pipeline.py", line 49, in <module>
    import r0AverageTest as r0AverageTest
  File "/Users/rohit/Documents/randomExperiments/r0AverageTest.py", line 17, in <module>
    import regressions as rgx
  File "/Users/rohit/Documents/randomExperiments/regressions.py", line 109
    return round(coeffs[0]*b + coeffs[1], 2)
    ^
IndentationError: expected an indented block
2020-04-27 21:13:43,212 - __mp_main__ - ERROR - Uncaught exception
Traceback (most recent call last):
  File "<string>", line 1, in <module>
  File "/Library/Frameworks/Python.framework/Versions/3.8/lib/python3.8/multiprocessing/spawn.py", line 116, in spawn_main
    exitcode = _main(fd, parent_sentinel)
  File "/Library/Frameworks/Python.framework/Versions/3.8/lib/python3.8/multiprocessing/spawn.py", line 125, in _main
    prepare(preparation_data)
  File "/Library/Frameworks/Python.framework/Versions/3.8/lib/python3.8/multiprocessing/spawn.py", line 236, in prepare
    _fixup_main_from_path(data['init_main_from_path'])
  File "/Library/Frameworks/Python.framework/Versions/3.8/lib/python3.8/multiprocessing/spawn.py", line 287, in _fixup_main_from_path
    main_content = runpy.run_path(main_path,
  File "/Library/Frameworks/Python.framework/Versions/3.8/lib/python3.8/runpy.py", line 263, in run_path
    return _run_module_code(code, init_globals, run_name,
  File "/Library/Frameworks/Python.framework/Versions/3.8/lib/python3.8/runpy.py", line 96, in _run_module_code
    _run_code(code, mod_globals, init_globals,
  File "/Library/Frameworks/Python.framework/Versions/3.8/lib/python3.8/runpy.py", line 86, in _run_code
    exec(code, run_globals)
  File "/Users/rohit/Documents/randomExperiments/pipeline.py", line 49, in <module>
    import r0AverageTest as r0AverageTest
  File "/Users/rohit/Documents/randomExperiments/r0AverageTest.py", line 17, in <module>
    import regressions as rgx
  File "/Users/rohit/Documents/randomExperiments/regressions.py", line 109
    return round(coeffs[0]*b + coeffs[1], 2)
    ^
IndentationError: expected an indented block
2020-04-27 21:13:43,221 - __mp_main__ - ERROR - Uncaught exception
Traceback (most recent call last):
  File "<string>", line 1, in <module>
  File "/Library/Frameworks/Python.framework/Versions/3.8/lib/python3.8/multiprocessing/spawn.py", line 116, in spawn_main
    exitcode = _main(fd, parent_sentinel)
  File "/Library/Frameworks/Python.framework/Versions/3.8/lib/python3.8/multiprocessing/spawn.py", line 125, in _main
    prepare(preparation_data)
  File "/Library/Frameworks/Python.framework/Versions/3.8/lib/python3.8/multiprocessing/spawn.py", line 236, in prepare
    _fixup_main_from_path(data['init_main_from_path'])
  File "/Library/Frameworks/Python.framework/Versions/3.8/lib/python3.8/multiprocessing/spawn.py", line 287, in _fixup_main_from_path
    main_content = runpy.run_path(main_path,
  File "/Library/Frameworks/Python.framework/Versions/3.8/lib/python3.8/runpy.py", line 263, in run_path
    return _run_module_code(code, init_globals, run_name,
  File "/Library/Frameworks/Python.framework/Versions/3.8/lib/python3.8/runpy.py", line 96, in _run_module_code
    _run_code(code, mod_globals, init_globals,
  File "/Library/Frameworks/Python.framework/Versions/3.8/lib/python3.8/runpy.py", line 86, in _run_code
    exec(code, run_globals)
  File "/Users/rohit/Documents/randomExperiments/pipeline.py", line 49, in <module>
    import r0AverageTest as r0AverageTest
  File "/Users/rohit/Documents/randomExperiments/r0AverageTest.py", line 17, in <module>
    import regressions as rgx
  File "/Users/rohit/Documents/randomExperiments/regressions.py", line 109
    return round(coeffs[0]*b + coeffs[1], 2)
    ^
IndentationError: expected an indented block
2020-04-27 21:13:46,427 - __mp_main__ - ERROR - Uncaught exception
Traceback (most recent call last):
  File "<string>", line 1, in <module>
  File "/Library/Frameworks/Python.framework/Versions/3.8/lib/python3.8/multiprocessing/spawn.py", line 116, in spawn_main
    exitcode = _main(fd, parent_sentinel)
  File "/Library/Frameworks/Python.framework/Versions/3.8/lib/python3.8/multiprocessing/spawn.py", line 125, in _main
    prepare(preparation_data)
  File "/Library/Frameworks/Python.framework/Versions/3.8/lib/python3.8/multiprocessing/spawn.py", line 236, in prepare
    _fixup_main_from_path(data['init_main_from_path'])
  File "/Library/Frameworks/Python.framework/Versions/3.8/lib/python3.8/multiprocessing/spawn.py", line 287, in _fixup_main_from_path
    main_content = runpy.run_path(main_path,
  File "/Library/Frameworks/Python.framework/Versions/3.8/lib/python3.8/runpy.py", line 263, in run_path
    return _run_module_code(code, init_globals, run_name,
  File "/Library/Frameworks/Python.framework/Versions/3.8/lib/python3.8/runpy.py", line 96, in _run_module_code
    _run_code(code, mod_globals, init_globals,
  File "/Library/Frameworks/Python.framework/Versions/3.8/lib/python3.8/runpy.py", line 86, in _run_code
    exec(code, run_globals)
  File "/Users/rohit/Documents/randomExperiments/pipeline.py", line 49, in <module>
    import r0AverageTest as r0AverageTest
  File "/Users/rohit/Documents/randomExperiments/r0AverageTest.py", line 17, in <module>
    import regressions as rgx
  File "/Users/rohit/Documents/randomExperiments/regressions.py", line 109
    return round(coeffs[0]*b + coeffs[1], 2)
    ^
IndentationError: expected an indented block
2020-04-27 21:13:47,319 - __mp_main__ - ERROR - Uncaught exception
Traceback (most recent call last):
  File "<string>", line 1, in <module>
  File "/Library/Frameworks/Python.framework/Versions/3.8/lib/python3.8/multiprocessing/spawn.py", line 116, in spawn_main
    exitcode = _main(fd, parent_sentinel)
  File "/Library/Frameworks/Python.framework/Versions/3.8/lib/python3.8/multiprocessing/spawn.py", line 125, in _main
    prepare(preparation_data)
  File "/Library/Frameworks/Python.framework/Versions/3.8/lib/python3.8/multiprocessing/spawn.py", line 236, in prepare
    _fixup_main_from_path(data['init_main_from_path'])
  File "/Library/Frameworks/Python.framework/Versions/3.8/lib/python3.8/multiprocessing/spawn.py", line 287, in _fixup_main_from_path
    main_content = runpy.run_path(main_path,
  File "/Library/Frameworks/Python.framework/Versions/3.8/lib/python3.8/runpy.py", line 263, in run_path
    return _run_module_code(code, init_globals, run_name,
  File "/Library/Frameworks/Python.framework/Versions/3.8/lib/python3.8/runpy.py", line 96, in _run_module_code
    _run_code(code, mod_globals, init_globals,
  File "/Library/Frameworks/Python.framework/Versions/3.8/lib/python3.8/runpy.py", line 86, in _run_code
    exec(code, run_globals)
  File "/Users/rohit/Documents/randomExperiments/pipeline.py", line 49, in <module>
    import r0AverageTest as r0AverageTest
  File "/Users/rohit/Documents/randomExperiments/r0AverageTest.py", line 17, in <module>
    import regressions as rgx
  File "/Users/rohit/Documents/randomExperiments/regressions.py", line 109
    return round(coeffs[0]*b + coeffs[1], 2)
    ^
IndentationError: expected an indented block
2020-04-27 21:13:48,522 - __mp_main__ - ERROR - Uncaught exception
Traceback (most recent call last):
  File "<string>", line 1, in <module>
  File "/Library/Frameworks/Python.framework/Versions/3.8/lib/python3.8/multiprocessing/spawn.py", line 116, in spawn_main
    exitcode = _main(fd, parent_sentinel)
  File "/Library/Frameworks/Python.framework/Versions/3.8/lib/python3.8/multiprocessing/spawn.py", line 125, in _main
    prepare(preparation_data)
  File "/Library/Frameworks/Python.framework/Versions/3.8/lib/python3.8/multiprocessing/spawn.py", line 236, in prepare
    _fixup_main_from_path(data['init_main_from_path'])
  File "/Library/Frameworks/Python.framework/Versions/3.8/lib/python3.8/multiprocessing/spawn.py", line 287, in _fixup_main_from_path
    main_content = runpy.run_path(main_path,
  File "/Library/Frameworks/Python.framework/Versions/3.8/lib/python3.8/runpy.py", line 263, in run_path
    return _run_module_code(code, init_globals, run_name,
  File "/Library/Frameworks/Python.framework/Versions/3.8/lib/python3.8/runpy.py", line 96, in _run_module_code
    _run_code(code, mod_globals, init_globals,
  File "/Library/Frameworks/Python.framework/Versions/3.8/lib/python3.8/runpy.py", line 86, in _run_code
    exec(code, run_globals)
  File "/Users/rohit/Documents/randomExperiments/pipeline.py", line 49, in <module>
    import r0AverageTest as r0AverageTest
  File "/Users/rohit/Documents/randomExperiments/r0AverageTest.py", line 17, in <module>
    import regressions as rgx
  File "/Users/rohit/Documents/randomExperiments/regressions.py", line 109
    return round(coeffs[0]*b + coeffs[1], 2)
    ^
IndentationError: expected an indented block
2020-04-27 21:13:52,712 - __mp_main__ - ERROR - Uncaught exception
Traceback (most recent call last):
  File "<string>", line 1, in <module>
  File "/Library/Frameworks/Python.framework/Versions/3.8/lib/python3.8/multiprocessing/spawn.py", line 116, in spawn_main
    exitcode = _main(fd, parent_sentinel)
  File "/Library/Frameworks/Python.framework/Versions/3.8/lib/python3.8/multiprocessing/spawn.py", line 125, in _main
    prepare(preparation_data)
  File "/Library/Frameworks/Python.framework/Versions/3.8/lib/python3.8/multiprocessing/spawn.py", line 236, in prepare
    _fixup_main_from_path(data['init_main_from_path'])
  File "/Library/Frameworks/Python.framework/Versions/3.8/lib/python3.8/multiprocessing/spawn.py", line 287, in _fixup_main_from_path
    main_content = runpy.run_path(main_path,
  File "/Library/Frameworks/Python.framework/Versions/3.8/lib/python3.8/runpy.py", line 263, in run_path
    return _run_module_code(code, init_globals, run_name,
  File "/Library/Frameworks/Python.framework/Versions/3.8/lib/python3.8/runpy.py", line 96, in _run_module_code
    _run_code(code, mod_globals, init_globals,
  File "/Library/Frameworks/Python.framework/Versions/3.8/lib/python3.8/runpy.py", line 86, in _run_code
    exec(code, run_globals)
  File "/Users/rohit/Documents/randomExperiments/pipeline.py", line 49, in <module>
    import r0AverageTest as r0AverageTest
  File "/Users/rohit/Documents/randomExperiments/r0AverageTest.py", line 17, in <module>
    import regressions as rgx
  File "/Users/rohit/Documents/randomExperiments/regressions.py", line 109
    return round(coeffs[0]*b + coeffs[1], 2)
    ^
IndentationError: expected an indented block
2020-04-27 21:13:52,718 - __mp_main__ - ERROR - Uncaught exception
Traceback (most recent call last):
  File "<string>", line 1, in <module>
  File "/Library/Frameworks/Python.framework/Versions/3.8/lib/python3.8/multiprocessing/spawn.py", line 116, in spawn_main
    exitcode = _main(fd, parent_sentinel)
  File "/Library/Frameworks/Python.framework/Versions/3.8/lib/python3.8/multiprocessing/spawn.py", line 125, in _main
    prepare(preparation_data)
  File "/Library/Frameworks/Python.framework/Versions/3.8/lib/python3.8/multiprocessing/spawn.py", line 236, in prepare
    _fixup_main_from_path(data['init_main_from_path'])
  File "/Library/Frameworks/Python.framework/Versions/3.8/lib/python3.8/multiprocessing/spawn.py", line 287, in _fixup_main_from_path
    main_content = runpy.run_path(main_path,
  File "/Library/Frameworks/Python.framework/Versions/3.8/lib/python3.8/runpy.py", line 263, in run_path
    return _run_module_code(code, init_globals, run_name,
  File "/Library/Frameworks/Python.framework/Versions/3.8/lib/python3.8/runpy.py", line 96, in _run_module_code
    _run_code(code, mod_globals, init_globals,
  File "/Library/Frameworks/Python.framework/Versions/3.8/lib/python3.8/runpy.py", line 86, in _run_code
    exec(code, run_globals)
  File "/Users/rohit/Documents/randomExperiments/pipeline.py", line 49, in <module>
    import r0AverageTest as r0AverageTest
  File "/Users/rohit/Documents/randomExperiments/r0AverageTest.py", line 17, in <module>
    import regressions as rgx
  File "/Users/rohit/Documents/randomExperiments/regressions.py", line 109
    return round(coeffs[0]*b + coeffs[1], 2)
    ^
IndentationError: expected an indented block
2020-04-27 21:13:52,813 - __mp_main__ - ERROR - Uncaught exception
Traceback (most recent call last):
  File "<string>", line 1, in <module>
  File "/Library/Frameworks/Python.framework/Versions/3.8/lib/python3.8/multiprocessing/spawn.py", line 116, in spawn_main
    exitcode = _main(fd, parent_sentinel)
  File "/Library/Frameworks/Python.framework/Versions/3.8/lib/python3.8/multiprocessing/spawn.py", line 125, in _main
    prepare(preparation_data)
  File "/Library/Frameworks/Python.framework/Versions/3.8/lib/python3.8/multiprocessing/spawn.py", line 236, in prepare
    _fixup_main_from_path(data['init_main_from_path'])
  File "/Library/Frameworks/Python.framework/Versions/3.8/lib/python3.8/multiprocessing/spawn.py", line 287, in _fixup_main_from_path
    main_content = runpy.run_path(main_path,
  File "/Library/Frameworks/Python.framework/Versions/3.8/lib/python3.8/runpy.py", line 263, in run_path
    return _run_module_code(code, init_globals, run_name,
  File "/Library/Frameworks/Python.framework/Versions/3.8/lib/python3.8/runpy.py", line 96, in _run_module_code
    _run_code(code, mod_globals, init_globals,
  File "/Library/Frameworks/Python.framework/Versions/3.8/lib/python3.8/runpy.py", line 86, in _run_code
    exec(code, run_globals)
  File "/Users/rohit/Documents/randomExperiments/pipeline.py", line 49, in <module>
    import r0AverageTest as r0AverageTest
  File "/Users/rohit/Documents/randomExperiments/r0AverageTest.py", line 17, in <module>
    import regressions as rgx
  File "/Users/rohit/Documents/randomExperiments/regressions.py", line 109
    return round(coeffs[0]*b + coeffs[1], 2)
    ^
IndentationError: expected an indented block
2020-04-27 21:13:56,680 - __mp_main__ - ERROR - Uncaught exception
Traceback (most recent call last):
  File "<string>", line 1, in <module>
  File "/Library/Frameworks/Python.framework/Versions/3.8/lib/python3.8/multiprocessing/spawn.py", line 116, in spawn_main
    exitcode = _main(fd, parent_sentinel)
  File "/Library/Frameworks/Python.framework/Versions/3.8/lib/python3.8/multiprocessing/spawn.py", line 125, in _main
    prepare(preparation_data)
  File "/Library/Frameworks/Python.framework/Versions/3.8/lib/python3.8/multiprocessing/spawn.py", line 236, in prepare
    _fixup_main_from_path(data['init_main_from_path'])
  File "/Library/Frameworks/Python.framework/Versions/3.8/lib/python3.8/multiprocessing/spawn.py", line 287, in _fixup_main_from_path
    main_content = runpy.run_path(main_path,
  File "/Library/Frameworks/Python.framework/Versions/3.8/lib/python3.8/runpy.py", line 263, in run_path
    return _run_module_code(code, init_globals, run_name,
  File "/Library/Frameworks/Python.framework/Versions/3.8/lib/python3.8/runpy.py", line 96, in _run_module_code
    _run_code(code, mod_globals, init_globals,
  File "/Library/Frameworks/Python.framework/Versions/3.8/lib/python3.8/runpy.py", line 86, in _run_code
    exec(code, run_globals)
  File "/Users/rohit/Documents/randomExperiments/pipeline.py", line 49, in <module>
    import r0AverageTest as r0AverageTest
  File "/Users/rohit/Documents/randomExperiments/r0AverageTest.py", line 17, in <module>
    import regressions as rgx
  File "/Users/rohit/Documents/randomExperiments/regressions.py", line 109
    return round(coeffs[0]*b + coeffs[1], 2)
    ^
IndentationError: expected an indented block
2020-04-27 21:13:57,523 - __mp_main__ - ERROR - Uncaught exception
Traceback (most recent call last):
  File "<string>", line 1, in <module>
  File "/Library/Frameworks/Python.framework/Versions/3.8/lib/python3.8/multiprocessing/spawn.py", line 116, in spawn_main
    exitcode = _main(fd, parent_sentinel)
  File "/Library/Frameworks/Python.framework/Versions/3.8/lib/python3.8/multiprocessing/spawn.py", line 125, in _main
    prepare(preparation_data)
  File "/Library/Frameworks/Python.framework/Versions/3.8/lib/python3.8/multiprocessing/spawn.py", line 236, in prepare
    _fixup_main_from_path(data['init_main_from_path'])
  File "/Library/Frameworks/Python.framework/Versions/3.8/lib/python3.8/multiprocessing/spawn.py", line 287, in _fixup_main_from_path
    main_content = runpy.run_path(main_path,
  File "/Library/Frameworks/Python.framework/Versions/3.8/lib/python3.8/runpy.py", line 263, in run_path
    return _run_module_code(code, init_globals, run_name,
  File "/Library/Frameworks/Python.framework/Versions/3.8/lib/python3.8/runpy.py", line 96, in _run_module_code
    _run_code(code, mod_globals, init_globals,
  File "/Library/Frameworks/Python.framework/Versions/3.8/lib/python3.8/runpy.py", line 86, in _run_code
    exec(code, run_globals)
  File "/Users/rohit/Documents/randomExperiments/pipeline.py", line 49, in <module>
    import r0AverageTest as r0AverageTest
  File "/Users/rohit/Documents/randomExperiments/r0AverageTest.py", line 17, in <module>
    import regressions as rgx
  File "/Users/rohit/Documents/randomExperiments/regressions.py", line 109
    return round(coeffs[0]*b + coeffs[1], 2)
    ^
IndentationError: expected an indented block
2020-04-27 21:13:58,434 - __mp_main__ - ERROR - Uncaught exception
Traceback (most recent call last):
  File "<string>", line 1, in <module>
  File "/Library/Frameworks/Python.framework/Versions/3.8/lib/python3.8/multiprocessing/spawn.py", line 116, in spawn_main
    exitcode = _main(fd, parent_sentinel)
  File "/Library/Frameworks/Python.framework/Versions/3.8/lib/python3.8/multiprocessing/spawn.py", line 125, in _main
    prepare(preparation_data)
  File "/Library/Frameworks/Python.framework/Versions/3.8/lib/python3.8/multiprocessing/spawn.py", line 236, in prepare
    _fixup_main_from_path(data['init_main_from_path'])
  File "/Library/Frameworks/Python.framework/Versions/3.8/lib/python3.8/multiprocessing/spawn.py", line 287, in _fixup_main_from_path
    main_content = runpy.run_path(main_path,
  File "/Library/Frameworks/Python.framework/Versions/3.8/lib/python3.8/runpy.py", line 263, in run_path
    return _run_module_code(code, init_globals, run_name,
  File "/Library/Frameworks/Python.framework/Versions/3.8/lib/python3.8/runpy.py", line 96, in _run_module_code
    _run_code(code, mod_globals, init_globals,
  File "/Library/Frameworks/Python.framework/Versions/3.8/lib/python3.8/runpy.py", line 86, in _run_code
    exec(code, run_globals)
  File "/Users/rohit/Documents/randomExperiments/pipeline.py", line 49, in <module>
    import r0AverageTest as r0AverageTest
  File "/Users/rohit/Documents/randomExperiments/r0AverageTest.py", line 17, in <module>
    import regressions as rgx
  File "/Users/rohit/Documents/randomExperiments/regressions.py", line 109
    return round(coeffs[0]*b + coeffs[1], 2)
    ^
IndentationError: expected an indented block
